Workbook

Sheet Summary
A1: Local Government TAM — National Summary
A2: Counts and estimated annual operating spend by state and population bucket. School districts excluded.
A3: Source: 2022 Census of Governments + Annual Survey of State and Local Govt Finances. Refreshed 2026-05-01.
A5: ENTITY COUNT BY STATE × BUCKET (counties + munis + townships)
A6: State | B6: <1K | C6: 1K-5K | D6: 5K-10K | E6: 10K-20K | F6: 20K-50K | G6: 50K-100K | H6: 100K+ | I6: Special Districts | J6: TOTAL ENTITIES | K6: TOTAL TAM ($M)
A7: AL | B7: 179 | C7: 153 | D7: 62 | E7: 53 | F7: 46 | G7: 20 | H7: 15 | I7: 540 | J7: =SUM(B7:I7) | K7: ='AL'!B22/1000000
A8: AK | B8: 66 | C8: 50 | D8: 17 | E8: 13 | F8: 10 | G8: 4 | H8: 2 | I8: 15 | J8: =SUM(B8:I8) | K8: ='AK'!B22/1000000
A9: AZ | B9: 27 | C9: 27 | D9: 13 | E9: 12 | F9: 13 | G9: 7 | H9: 7 | I9: 318 | J9: =SUM(B9:I9) | K9: ='AZ'!B22/1000000
A10: AR | B10: 195 | C10: 167 | D10: 68 | E10: 58 | F10: 51 | G10: 21 | H10: 17 | I10: 723 | J10: =SUM(B10:I10) | K10: ='AR'!B22/1000000
A11: CA | B11: 111 | C11: 123 | D11: 66 | E11: 72 | F11: 82 | G11: 43 | H11: 43 | I11: 2767 | J11: =SUM(B11:I11) | K11: ='CA'!B22/1000000
A12: CO | B12: 81 | C12: 82 | D12: 41 | E12: 39 | F12: 44 | G12: 23 | H12: 23 | I12: 2540 | J12: =SUM(B12:I12) | K12: ='CO'!B22/1000000
A13: CT | B13: 77 | C13: 58 | D13: 19 | E13: 12 | F13: 9 | G13: 3 | H13: 1 | I13: 460 | J13: =SUM(B13:I13) | K13: ='CT'!B22/1000000
A14: DE | B14: 17 | C14: 17 | D14: 7 | E14: 6 | F14: 7 | G14: 3 | H14: 3 | I14: 256 | J14: =SUM(B14:I14) | K14: ='DE'!B22/1000000
A15: FL | B15: 95 | C15: 107 | D15: 57 | E15: 62 | F15: 74 | G15: 41 | H15: 42 | I15: 1134 | J15: =SUM(B15:I15) | K15: ='FL'!B22/1000000
A16: GA | B16: 189 | C16: 173 | D16: 81 | E16: 80 | F16: 83 | G16: 42 | H16: 42 | I16: 720 | J16: =SUM(B16:I16) | K16: ='GA'!B22/1000000
A17: HI | B17: 1 | C17: 0 | D17: 0 | E17: 0 | F17: 1 | G17: 1 | H17: 1 | I17: 17 | J17: =SUM(B17:I17) | K17: ='HI'!B22/1000000
A18: ID | B18: 78 | C18: 68 | D18: 29 | E18: 26 | F18: 24 | G18: 11 | H18: 8 | I18: 1058 | J18: =SUM(B18:I18) | K18: ='ID'!B22/1000000
A19: IL | B19: 864 | C19: 791 | D19: 342 | E19: 297 | F19: 295 | G19: 142 | H19: 100 | I19: 3050 | J19: =SUM(B19:I19) | K19: ='IL'!B22/1000000
A20: IN | B20: 703 | C20: 499 | D20: 169 | E20: 122 | F20: 100 | G20: 43 | H20: 29 | I20: 1262 | J20: =SUM(B20:I20) | K20: ='IN'!B22/1000000
A21: IA | B21: 422 | C21: 317 | D21: 115 | E21: 87 | F21: 64 | G21: 21 | H21: 14 | I21: 562 | J21: =SUM(B21:I21) | K21: ='IA'!B22/1000000
A22: KS | B22: 1007 | C22: 606 | D22: 171 | E22: 106 | F22: 70 | G22: 23 | H22: 12 | I22: 1535 | J22: =SUM(B22:I22) | K22: ='KS'!B22/1000000
A23: KY | B23: 162 | C23: 146 | D23: 64 | E23: 58 | F23: 57 | G23: 27 | H23: 22 | I23: 720 | J23: =SUM(B23:I23) | K23: ='KY'!B22/1000000
A24: LA | B24: 118 | C24: 104 | D24: 43 | E24: 38 | F24: 35 | G24: 15 | H24: 11 | I24: 95 | J24: =SUM(B24:I24) | K24: ='LA'!B22/1000000
A25: ME | B25: 278 | C25: 154 | D25: 37 | E25: 20 | F25: 12 | G25: 3 | H25: 1 | I25: 226 | J25: =SUM(B25:I25) | K25: ='ME'!B22/1000000
A26: MD | B26: 47 | C26: 46 | D26: 22 | E26: 22 | F26: 22 | G26: 10 | H26: 11 | I26: 90 | J26: =SUM(B26:I26) | K26: ='MD'!B22/1000000
A27: MA | B27: 130 | C27: 109 | D27: 42 | E27: 31 | F27: 26 | G27: 13 | H27: 5 | I27: 480 | J27: =SUM(B27:I27) | K27: ='MA'!B22/1000000
A28: MI | B28: 807 | C28: 564 | D28: 185 | E28: 129 | F28: 101 | G28: 42 | H28: 28 | I28: 451 | J28: =SUM(B28:I28) | K28: ='MI'!B22/1000000
A29: MN | B29: 1191 | C29: 833 | D29: 271 | E29: 189 | F29: 144 | G29: 59 | H29: 34 | I29: 482 | J29: =SUM(B29:I29) | K29: ='MN'!B22/1000000
A30: MS | B30: 116 | C30: 103 | D30: 45 | E30: 42 | F30: 40 | G30: 18 | H30: 15 | I30: 467 | J30: =SUM(B30:I30) | K30: ='MS'!B22/1000000
A31: MO | B31: 491 | C31: 395 | D31: 156 | E31: 130 | F31: 115 | G31: 51 | H31: 42 | I31: 1620 | J31: =SUM(B31:I31) | K31: ='MO'!B22/1000000
A32: MT | B32: 58 | C32: 49 | D32: 22 | E32: 21 | F32: 18 | G32: 7 | H32: 6 | I32: 813 | J32: =SUM(B32:I32) | K32: ='MT'!B22/1000000
A33: NE | B33: 477 | C33: 312 | D33: 100 | E33: 70 | F33: 52 | G33: 17 | H33: 10 | I33: 1300 | J33: =SUM(B33:I33) | K33: ='NE'!B22/1000000
A34: NV | B34: 6 | C34: 6 | D34: 4 | E34: 4 | F34: 6 | G34: 4 | H34: 5 | I34: 175 | J34: =SUM(B34:I34) | K34: ='NV'!B22/1000000
A35: NH | B35: 121 | C35: 76 | D35: 21 | E35: 12 | F35: 9 | G35: 4 | H35: 1 | I35: 142 | J35: =SUM(B35:I35) | K35: ='NH'!B22/1000000
A36: NJ | B36: 130 | C36: 143 | D36: 75 | E36: 77 | F36: 84 | G36: 41 | H36: 36 | I36: 281 | J36: =SUM(B36:I36) | K36: ='NJ'!B22/1000000
A37: NM | B37: 41 | C37: 37 | D37: 16 | E37: 15 | F37: 16 | G37: 7 | H37: 6 | I37: 685 | J37: =SUM(B37:I37) | K37: ='NM'!B22/1000000
A38: NY | B38: 510 | C38: 457 | D38: 192 | E38: 162 | F38: 158 | G38: 76 | H38: 49 | I38: 1183 | J38: =SUM(B38:I38) | K38: ='NY'!B22/1000000
A39: NC | B39: 194 | C39: 174 | D39: 77 | E39: 72 | F39: 70 | G39: 34 | H39: 31 | I39: 311 | J39: =SUM(B39:I39) | K39: ='NC'!B22/1000000
A40: ND | B40: 912 | C40: 526 | D40: 138 | E40: 77 | F40: 47 | G40: 14 | H40: 7 | I40: 763 | J40: =SUM(B40:I40) | K40: ='ND'!B22/1000000
A41: OH | B41: 983 | C41: 707 | D41: 240 | E41: 174 | F41: 137 | G41: 56 | H41: 36 | I41: 776 | J41: =SUM(B41:I41) | K41: ='OH'!B22/1000000
...

Sheet Methodology
A1: Methodology
A3: Scope
A4: U.S. local-government software market. Entity types tracked: counties / parishes, incorporated municipalities, organized townships, special districts. School districts and federal/state agencies are excluded.
A6: Population buckets
A7: <1K, 1K-5K, 5K-10K, 10K-20K, 20K-50K, 50K-100K, 100K+. Applied to munis, counties, and townships. Special districts are not population-bucketed (size driven by purpose — water, fire, transit — not by population).
A9: Entity counts
A10: Sourced from the 2022 Census of Governments. Per-state counts encoded in data.py. National totals reconcile to Census within ~1-3% (rounding from compilation of state-by-state filings).
A12: Bucket distribution
A13: National baseline distribution per entity type, multiplied by state-level skew profiles (urban_strong / urban_mild / balanced / rural_mild / rural_strong) and renormalized so each state's distribution sums to 100% per entity type.
A15: Spend math
A16: TAM_per_cell = entity_count × avg_bucket_population × per_capita_spend. Per-capita spend is anchored to Census Annual Survey of State and Local Government Finances 2022. Special district spend uses a flat $7.6M average annual operating spend per district. National total lands within ±10% of Census $2.2T figure; deviation reflects the fact that this TAM model counts each entity's spend independently (reflects software customer count) rather than netting overlapping jurisdictions.
A18: Color coding
... A28: Each vendor's published customer total is allocated across states using HQ-state weighting, named case-study customers, acquired-company home/service states, state-specific marketing presence, and a population-weighted residual. Per-state sums calibrated to land within ±15% of each vendor's published total.

Sheet AL
A1: AL — Alabama
A2: Counts and estimated annual operating spend by entity type and bucket.
A4: Entity / Bucket | B4: Count | C4: Avg Pop | D4: $/capita | E4: Spend ($)
A5: Municipalities
A6: <1K | B6: 178 | C6: 450 | D6: 2000 | E6: 160200000
A7: 1K-5K | B7: 146 | C7: 2700 | D7: 2500 | E7: 985500000
A8: 5K-10K | B8: 53 | C8: 7100 | D8: 3000 | E8: 1128900000
A9: 10K-20K | B9: 40 | C9: 14000 | D9: 3500 | E9: 1960000000
A10: 20K-50K | B10: 29 | C10: 31000 | D10: 4200 | E10: 3775800000
A11: 50K-100K | B11: 10 | C11: 70000 | D11: 4800 | E11: 3360000000
A12: 100K+ | B12: 5 | C12: 220000 | D12: 7000 | E12: 7700000000
A13: Municipalities subtotal | B13: 461 | E13: 19070400000
A15: Counties / Parishes
A16: <1K | B16: 1 | C16: 450 | D16: 3500 | E16: 1575000
A17: 1K-5K | B17: 7 | C17: 2700 | D17: 3300 | E17: 62370000
A18: 5K-10K | B18: 9 | C18: 7100 | D18: 2900 | E18: 185310000
A19: 10K-20K | B19: 13 | C19: 14000 | D19: 2700 | E19: 491400000
A20: 20K-50K | B20: 17 | C20: 31000 | D20: 2900 | E20: 1528300000
A21: 50K-100K | B21: 10 | C21: 70000 | D21: 3200 | E21: 2240000000
A22: GRAND TOTAL | B22: =B13+B23+B27 | C22: 220000 | D22: 3500 | E22: =E13+E23+E27
A23: Counties / Parishes subtotal | B23: =SUM(B16:B22) | E23: =SUM(E16:E22)
A25: Special Districts
A26: (all sizes) | B26: 540 | D26: 7600000 | E26: 4104000000
A27: Special Districts subtotal | B27: 540 | E27: 4104000000

Sheet AK
A1: AK — Alaska
A2: Counts and estimated annual operating spend by entity type and bucket.
A4: Entity / Bucket | B4: Count | C4: Avg Pop | D4: $/capita | E4: Spend ($)
A5: Municipalities
A6: <1K | B6: 66 | C6: 450 | D6: 2000 | E6: 59400000
A7: 1K-5K | B7: 48 | C7: 2700 | D7: 2500 | E7: 324000000
A8: 5K-10K | B8: 15 | C8: 7100 | D8: 3000 | E8: 319500000
A9: 10K-20K | B9: 10 | C9: 14000 | D9: 3500 | E9: 490000000
A10: 20K-50K | B10: 6 | C10: 31000 | D10: 4200 | E10: 781200000
A11: 50K-100K | B11: 2 | C11: 70000 | D11: 4800 | E11: 672000000
A12: 100K+ | B12: 1 | C12: 220000 | D12: 7000 | E12: 1540000000
A13: Municipalities subtotal | B13: 148 | E13: 4186100000
A15: Counties / Parishes
A16: <1K | B16: 0 | C16: 450 | D16: 3500 | E16: 0
A17: 1K-5K | B17: 2 | C17: 2700 | D17: 3300 | E17: 17820000
A18: 5K-10K | B18: 2 | C18: 7100 | D18: 2900 | E18: 41180000
A19: 10K-20K | B19: 3 | C19: 14000 | D19: 2700 | E19: 113400000
A20: 20K-50K | B20: 4 | C20: 31000 | D20: 2900 | E20: 359600000
A21: 50K-100K | B21: 2 | C21: 70000 | D21: 3200 | E21: 448000000
A22: GRAND TOTAL | B22: =B13+B23+B27 | C22: 220000 | D22: 3500 | E22: =E13+E23+E27
A23: Counties / Parishes subtotal | B23: =SUM(B16:B22) | E23: =SUM(E16:E22)
A25: Special Districts
A26: (all sizes) | B26: 15 | D26: 7600000 | E26: 114000000
A27: Special Districts subtotal | B27: 15 | E27: 114000000

Sheet AZ
A1: AZ — Arizona
A2: Counts and estimated annual operating spend by entity type and bucket.
A4: Entity / Bucket | B4: Count | C4: Avg Pop | D4: $/capita | E4: Spend ($)
A5: Municipalities
A6: <1K | B6: 27 | C6: 450 | D6: 2000 | E6: 24300000
A7: 1K-5K | B7: 26 | C7: 2700 | D7: 2500 | E7: 175500000
A8: 5K-10K | B8: 12 | C8: 7100 | D8: 3000 | E8: 255600000
A9: 10K-20K | B9: 10 | C9: 14000 | D9: 3500 | E9: 490000000
A10: 20K-50K | B10: 9 | C10: 31000 | D10: 4200 | E10: 1171800000
A11: 50K-100K | B11: 4 | C11: 70000 | D11: 4800 | E11: 1344000000
A12: 100K+ | B12: 3 | C12: 220000 | D12: 7000 | E12: 4620000000
A13: Municipalities subtotal | B13: 91 | E13: 8081200000
A15: Counties / Parishes
A16: <1K | B16: 0 | C16: 450 | D16: 3500 | E16: 0
A17: 1K-5K | B17: 1 | C17: 2700 | D17: 3300 | E17: 8910000
A18: 5K-10K | B18: 1 | C18: 7100 | D18: 2900 | E18: 20590000
A19: 10K-20K | B19: 2 | C19: 14000 | D19: 2700 | E19: 75600000
A20: 20K-50K | B20: 4 | C20: 31000 | D20: 2900 | E20: 359600000
A21: 50K-100K | B21: 3 | C21: 70000 | D21: 3200 | E21: 672000000
A22: GRAND TOTAL | B22: =B13+B23+B27 | C22: 220000 | D22: 3500 | E22: =E13+E23+E27
A23: Counties / Parishes subtotal | B23: =SUM(B16:B22) | E23: =SUM(E16:E22)
A25: Special Districts
A26: (all sizes) | B26: 318 | D26: 7600000 | E26: 2416800000
A27: Special Districts subtotal | B27: 318 | E27: 2416800000

Sheet AR
A1: AR — Arkansas
A2: Counts and estimated annual operating spend by entity type and bucket.
A4: Entity / Bucket | B4: Count | C4: Avg Pop | D4: $/capita | E4: Spend ($)
A5: Municipalities
A6: <1K | B6: 194 | C6: 450 | D6: 2000 | E6: 174600000
A7: 1K-5K | B7: 159 | C7: 2700 | D7: 2500 | E7: 1073250000
A8: 5K-10K | B8: 58 | C8: 7100 | D8: 3000 | E8: 1235400000
A9: 10K-20K | B9: 44 | C9: 14000 | D9: 3500 | E9: 2156000000
A10: 20K-50K | B10: 31 | C10: 31000 | D10: 4200 | E10: 4036200000
A11: 50K-100K | B11: 10 | C11: 70000 | D11: 4800 | E11: 3360000000
A12: 100K+ | B12: 6 | C12: 220000 | D12: 7000 | E12: 9240000000
A13: Municipalities subtotal | B13: 502 | E13: 21275450000
A15: Counties / Parishes
A16: <1K | B16: 1 | C16: 450 | D16: 3500 | E16: 1575000
A17: 1K-5K | B17: 8 | C17: 2700 | D17: 3300 | E17: 71280000
A18: 5K-10K | B18: 10 | C18: 7100 | D18: 2900 | E18: 205900000
A19: 10K-20K | B19: 14 | C19: 14000 | D19: 2700 | E19: 529200000
A20: 20K-50K | B20: 20 | C20: 31000 | D20: 2900 | E20: 1798000000
A21: 50K-100K | B21: 11 | C21: 70000 | D21: 3200 | E21: 2464000000
A22: GRAND TOTAL | B22: =B13+B23+B27 | C22: 220000 | D22: 3500 | E22: =E13+E23+E27
A23: Counties / Parishes subtotal | B23: =SUM(B16:B22) | E23: =SUM(E16:E22)
A25: Special Districts
A26: (all sizes) | B26: 723 | D26: 7600000 | E26: 5494800000
A27: Special Districts subtotal | B27: 723 | E27: 5494800000

Sheet CA
A1: CA — California
A2: Counts and estimated annual operating spend by entity type and bucket.
A4: Entity / Bucket | B4: Count | C4: Avg Pop | D4: $/capita | E4: Spend ($)
A5: Municipalities
A6: <1K | B6: 111 | C6: 450 | D6: 2000 | E6: 99900000
A7: 1K-5K | B7: 121 | C7: 2700 | D7: 2500 | E7: 816750000
A8: 5K-10K | B8: 62 | C8: 7100 | D8: 3000 | E8: 1320600000
A9: 10K-20K | B9: 64 | C9: 14000 | D9: 3500 | E9: 3136000000
A10: 20K-50K | B10: 67 | C10: 31000 | D10: 4200 | E10: 8723400000
A11: 50K-100K | B11: 31 | C11: 70000 | D11: 4800 | E11: 10416000000
A12: 100K+ | B12: 26 | C12: 220000 | D12: 7000 | E12: 40040000000
A13: Municipalities subtotal | B13: 482 | E13: 64552650000
A15: Counties / Parishes
A16: <1K | B16: 0 | C16: 450 | D16: 3500 | E16: 0
A17: 1K-5K | B17: 2 | C17: 2700 | D17: 3300 | E17: 17820000
A18: 5K-10K | B18: 4 | C18: 7100 | D18: 2900 | E18: 82360000
A19: 10K-20K | B19: 8 | C19: 14000 | D19: 2700 | E19: 302400000
A20: 20K-50K | B20: 15 | C20: 31000 | D20: 2900 | E20: 1348500000
A21: 50K-100K | B21: 12 | C21: 70000 | D21: 3200 | E21: 2688000000
A22: GRAND TOTAL | B22: =B13+B23+B27 | C22: 220000 | D22: 3500 | E22: =E13+E23+E27
A23: Counties / Parishes subtotal | B23: =SUM(B16:B22) | E23: =SUM(E16:E22)
A25: Special Districts
A26: (all sizes) | B26: 2767 | D26: 7600000 | E26: 21029200000
A27: Special Districts subtotal | B27: 2767 | E27: 21029200000

Sheet CO
A1: CO — Colorado
A2: Counts and estimated annual operating spend by entity type and bucket.
A4: Entity / Bucket | B4: Count | C4: Avg Pop | D4: $/capita | E4: Spend ($)
A5: Municipalities
A6: <1K | B6: 81 | C6: 450 | D6: 2000 | E6: 72900000
A7: 1K-5K | B7: 78 | C7: 2700 | D7: 2500 | E7: 526500000
A8: 5K-10K | B8: 35 | C8: 7100 | D8: 3000 | E8: 745500000
A9: 10K-20K | B9: 30 | C9: 14000 | D9: 3500 | E9: 1470000000
A10: 20K-50K | B10: 28 | C10: 31000 | D10: 4200 | E10: 3645600000
A11: 50K-100K | B11: 11 | C11: 70000 | D11: 4800 | E11: 3696000000
A12: 100K+ | B12: 8 | C12: 220000 | D12: 7000 | E12: 12320000000
A13: Municipalities subtotal | B13: 271 | E13: 22476500000
A15: Counties / Parishes
A16: <1K | B16: 0 | C16: 450 | D16: 3500 | E16: 0
A17: 1K-5K | B17: 4 | C17: 2700 | D17: 3300 | E17: 35640000
A18: 5K-10K | B18: 6 | C18: 7100 | D18: 2900 | E18: 123540000
A19: 10K-20K | B19: 9 | C19: 14000 | D19: 2700 | E19: 340200000
A20: 20K-50K | B20: 16 | C20: 31000 | D20: 2900 | E20: 1438400000
A21: 50K-100K | B21: 12 | C21: 70000 | D21: 3200 | E21: 2688000000
A22: GRAND TOTAL | B22: =B13+B23+B27 | C22: 220000 | D22: 3500 | E22: =E13+E23+E27
A23: Counties / Parishes subtotal | B23: =SUM(B16:B22) | E23: =SUM(E16:E22)
A25: Special Districts
A26: (all sizes) | B26: 2540 | D26: 7600000 | E26: 19304000000
A27: Special Districts subtotal | B27: 2540 | E27: 19304000000

Sheet CT
A1: CT — Connecticut
A2: Counts and estimated annual operating spend by entity type and bucket.
A4: Entity / Bucket | B4: Count | C4: Avg Pop | D4: $/capita | E4: Spend ($)
A5: Municipalities
A6: <1K | B6: 9 | C6: 450 | D6: 2000 | E6: 8100000
A7: 1K-5K | B7: 9 | C7: 2700 | D7: 2500 | E7: 60750000
A8: 5K-10K | B8: 4 | C8: 7100 | D8: 3000 | E8: 85200000
A9: 10K-20K | B9: 3 | C9: 14000 | D9: 3500 | E9: 147000000
A10: 20K-50K | B10: 3 | C10: 31000 | D10: 4200 | E10: 390600000
A11: 50K-100K | B11: 1 | C11: 70000 | D11: 4800 | E11: 336000000
A12: 100K+ | B12: 1 | C12: 220000 | D12: 7000 | E12: 1540000000
A13: Municipalities subtotal | B13: 30 | E13: 2567650000
A15: Counties / Parishes
A16: <1K | B16: 0 | C16: 450 | D16: 3500 | E16: 0
A17: 1K-5K | B17: 0 | C17: 2700 | D17: 3300 | E17: 0
A18: 5K-10K | B18: 0 | C18: 7100 | D18: 2900 | E18: 0
A19: 10K-20K | B19: 0 | C19: 14000 | D19: 2700 | E19: 0
A20: 20K-50K | B20: 0 | C20: 31000 | D20: 2900 | E20: 0
A21: 50K-100K | B21: 0 | C21: 70000 | D21: 3200 | E21: 0
A22: GRAND TOTAL | B22: =B13+B23+B33+B37 | C22: 220000 | D22: 3500 | E22: =E13+E23+E33+E37
A23: Counties / Parishes subtotal | B23: =SUM(B16:B22) | E23: =SUM(E16:E22)
A25: Townships
A26: <1K | B26: 68 | C26: 450 | D26: 600 | E26: 18360000
A27: 1K-5K | B27: 49 | C27: 2700 | D27: 800 | E27: 105840000
A28: 5K-10K | B28: 15 | C28: 7100 | D28: 1100 | E28: 117150000
A29: 10K-20K | B29: 9 | C29: 14000 | D29: 1400 | E29: 176400000
A30: 20K-50K | B30: 6 | C30: 31000 | D30: 1600 | E30: 297600000
A31: 50K-100K | B31: 2 | C31: 70000 | D31: 1700 | E31: 238000000
A32: 100K+ | B32: 0 | C32: 220000 | D32: 1800 | E32: 0
A33: Townships subtotal | B33: 149 | E33: 953350000
A35: Special Districts
A36: (all sizes) | B36: 460 | D36: 7600000 | E36: 3496000000
A37: Special Districts subtotal | B37: 460 | E37: 3496000000

Sheet DE
A1: DE — Delaware
A2: Counts and estimated annual operating spend by entity type and bucket.
A4: Entity / Bucket | B4: Count | C4: Avg Pop | D4: $/capita | E4: Spend ($)
A5: Municipalities
A6: <1K | B6: 17 | C6: 450 | D6: 2000 | E6: 15300000
A7: 1K-5K | B7: 17 | C7: 2700 | D7: 2500 | E7: 114750000
A8: 5K-10K | B8: 7 | C8: 7100 | D8: 3000 | E8: 149100000
A9: 10K-20K | B9: 6 | C9: 14000 | D9: 3500 | E9: 294000000
A10: 20K-50K | B10: 6 | C10: 31000 | D10: 4200 | E10: 781200000
A11: 50K-100K | B11: 2 | C11: 70000 | D11: 4800 | E11: 672000000
A12: 100K+ | B12: 2 | C12: 220000 | D12: 7000 | E12: 3080000000
A13: Municipalities subtotal | B13: 57 | E13: 5106350000
A15: Counties / Parishes
A16: <1K | B16: 0 | C16: 450 | D16: 3500 | E16: 0
A17: 1K-5K | B17: 0 | C17: 2700 | D17: 3300 | E17: 0
A18: 5K-10K | B18: 0 | C18: 7100 | D18: 2900 | E18: 0
A19: 10K-20K | B19: 0 | C19: 14000 | D19: 2700 | E19: 0
A20: 20K-50K | B20: 1 | C20: 31000 | D20: 2900 | E20: 89900000
A21: 50K-100K | B21: 1 | C21: 70000 | D21: 3200 | E21: 224000000
A22: GRAND TOTAL | B22: =B13+B23+B27 | C22: 220000 | D22: 3500 | E22: =E13+E23+E27
A23: Counties / Parishes subtotal | B23: =SUM(B16:B22) | E23: =SUM(E16:E22)
A25: Special Districts
A26: (all sizes) | B26: 256 | D26: 7600000 | E26: 1945600000
A27: Special Districts subtotal | B27: 256 | E27: 1945600000

Sheet FL
A1: FL — Florida
A2: Counts and estimated annual operating spend by entity type and bucket.
A4: Entity / Bucket | B4: Count | C4: Avg Pop | D4: $/capita | E4: Spend ($)
A5: Municipalities
A6: <1K | B6: 95 | C6: 450 | D6: 2000 | E6: 85500000
A7: 1K-5K | B7: 104 | C7: 2700 | D7: 2500 | E7: 702000000
A8: 5K-10K | B8: 53 | C8: 7100 | D8: 3000 | E8: 1128900000
A9: 10K-20K | B9: 54 | C9: 14000 | D9: 3500 | E9: 2646000000
A10: 20K-50K | B10: 57 | C10: 31000 | D10: 4200 | E10: 7421400000
A11: 50K-100K | B11: 27 | C11: 70000 | D11: 4800 | E11: 9072000000
A12: 100K+ | B12: 22 | C12: 220000 | D12: 7000 | E12: 33880000000
A13: Municipalities subtotal | B13: 412 | E13: 54935800000
A15: Counties / Parishes
A16: <1K | B16: 0 | C16: 450 | D16: 3500 | E16: 0
A17: 1K-5K | B17: 3 | C17: 2700 | D17: 3300 | E17: 26730000
A18: 5K-10K | B18: 4 | C18: 7100 | D18: 2900 | E18: 82360000
A19: 10K-20K | B19: 8 | C19: 14000 | D19: 2700 | E19: 302400000
A20: 20K-50K | B20: 17 | C20: 31000 | D20: 2900 | E20: 1528300000
A21: 50K-100K | B21: 14 | C21: 70000 | D21: 3200 | E21: 3136000000
A22: GRAND TOTAL | B22: =B13+B23+B27 | C22: 220000 | D22: 3500 | E22: =E13+E23+E27
A23: Counties / Parishes subtotal | B23: =SUM(B16:B22) | E23: =SUM(E16:E22)
A25: Special Districts
A26: (all sizes) | B26: 1134 | D26: 7600000 | E26: 8618400000
A27: Special Districts subtotal | B27: 1134 | E27: 8618400000

Sheet GA
A1: GA — Georgia
A2: Counts and estimated annual operating spend by entity type and bucket.
A4: Entity / Bucket | B4: Count | C4: Avg Pop | D4: $/capita | E4: Spend ($)
A5: Municipalities
A6: <1K | B6: 188 | C6: 450 | D6: 2000 | E6: 169200000
A7: 1K-5K | B7: 161 | C7: 2700 | D7: 2500 | E7: 1086750000
A8: 5K-10K | B8: 64 | C8: 7100 | D8: 3000 | E8: 1363200000
A9: 10K-20K | B9: 54 | C9: 14000 | D9: 3500 | E9: 2646000000
A10: 20K-50K | B10: 43 | C10: 31000 | D10: 4200 | E10: 5598600000
A11: 50K-100K | B11: 16 | C11: 70000 | D11: 4800 | E11: 5376000000
A12: 100K+ | B12: 11 | C12: 220000 | D12: 7000 | E12: 16940000000
A13: Municipalities subtotal | B13: 537 | E13: 33179750000
A15: Counties / Parishes
A16: <1K | B16: 1 | C16: 450 | D16: 3500 | E16: 1575000
A17: 1K-5K | B17: 12 | C17: 2700 | D17: 3300 | E17: 106920000
A18: 5K-10K | B18: 17 | C18: 7100 | D18: 2900 | E18: 350030000
A19: 10K-20K | B19: 26 | C19: 14000 | D19: 2700 | E19: 982800000
A20: 20K-50K | B20: 40 | C20: 31000 | D20: 2900 | E20: 3596000000
A21: 50K-100K | B21: 26 | C21: 70000 | D21: 3200 | E21: 5824000000
A22: GRAND TOTAL | B22: =B13+B23+B27 | C22: 220000 | D22: 3500 | E22: =E13+E23+E27
A23: Counties / Parishes subtotal | B23: =SUM(B16:B22) | E23: =SUM(E16:E22)
A25: Special Districts
A26: (all sizes) | B26: 720 | D26: 7600000 | E26: 5472000000
A27: Special Districts subtotal | B27: 720 | E27: 5472000000

Sheet HI
A1: HI — Hawaii
A2: Counts and estimated annual operating spend by entity type and bucket.
A4: Entity / Bucket | B4: Count | C4: Avg Pop | D4: $/capita | E4: Spend ($)
A5: Municipalities
A6: <1K | B6: 1 | C6: 450 | D6: 2000 | E6: 900000
A7: 1K-5K | B7: 0 | C7: 2700 | D7: 2500 | E7: 0
A8: 5K-10K | B8: 0 | C8: 7100 | D8: 3000 | E8: 0
A9: 10K-20K | B9: 0 | C9: 14000 | D9: 3500 | E9: 0
A10: 20K-50K | B10: 0 | C10: 31000 | D10: 4200 | E10: 0
A11: 50K-100K | B11: 0 | C11: 70000 | D11: 4800 | E11: 0
A12: 100K+ | B12: 0 | C12: 220000 | D12: 7000 | E12: 0
A13: Municipalities subtotal | B13: 1 | E13: 900000
A15: Counties / Parishes
A16: <1K | B16: 0 | C16: 450 | D16: 3500 | E16: 0
A17: 1K-5K | B17: 0 | C17: 2700 | D17: 3300 | E17: 0
A18: 5K-10K | B18: 0 | C18: 7100 | D18: 2900 | E18: 0
A19: 10K-20K | B19: 0 | C19: 14000 | D19: 2700 | E19: 0
A20: 20K-50K | B20: 1 | C20: 31000 | D20: 2900 | E20: 89900000
A21: 50K-100K | B21: 1 | C21: 70000 | D21: 3200 | E21: 224000000
A22: GRAND TOTAL | B22: =B13+B23+B27 | C22: 220000 | D22: 3500 | E22: =E13+E23+E27
A23: Counties / Parishes subtotal | B23: =SUM(B16:B22) | E23: =SUM(E16:E22)
A25: Special Districts
A26: (all sizes) | B26: 17 | D26: 7600000 | E26: 129200000
A27: Special Districts subtotal | B27: 17 | E27: 129200000

Sheet ID
A1: ID — Idaho
A2: Counts and estimated annual operating spend by entity type and bucket.
A4: Entity / Bucket | B4: Count | C4: Avg Pop | D4: $/capita | E4: Spend ($)
A5: Municipalities
A6: <1K | B6: 77 | C6: 450 | D6: 2000 | E6: 69300000
A7: 1K-5K | B7: 63 | C7: 2700 | D7: 2500 | E7: 425250000
A8: 5K-10K | B8: 23 | C8: 7100 | D8: 3000 | E8: 489900000
A9: 10K-20K | B9: 18 | C9: 14000 | D9: 3500 | E9: 882000000
A10: 20K-50K | B10: 13 | C10: 31000 | D10: 4200 | E10: 1692600000
A11: 50K-100K | B11: 4 | C11: 70000 | D11: 4800 | E11: 1344000000
A12: 100K+ | B12: 2 | C12: 220000 | D12: 7000 | E12: 3080000000
A13: Municipalities subtotal | B13: 200 | E13: 7983050000
A15: Counties / Parishes
A16: <1K | B16: 1 | C16: 450 | D16: 3500 | E16: 1575000
A17: 1K-5K | B17: 5 | C17: 2700 | D17: 3300 | E17: 44550000
A18: 5K-10K | B18: 6 | C18: 7100 | D18: 2900 | E18: 123540000
A19: 10K-20K | B19: 8 | C19: 14000 | D19: 2700 | E19: 302400000
A20: 20K-50K | B20: 11 | C20: 31000 | D20: 2900 | E20: 988900000
A21: 50K-100K | B21: 7 | C21: 70000 | D21: 3200 | E21: 1568000000
A22: GRAND TOTAL | B22: =B13+B23+B27 | C22: 220000 | D22: 3500 | E22: =E13+E23+E27
A23: Counties / Parishes subtotal | B23: =SUM(B16:B22) | E23: =SUM(E16:E22)
A25: Special Districts
A26: (all sizes) | B26: 1058 | D26: 7600000 | E26: 8040800000
A27: Special Districts subtotal | B27: 1058 | E27: 8040800000

Sheet IL
A1: IL — Illinois
A2: Counts and estimated annual operating spend by entity type and bucket.
A4: Entity / Bucket | B4: Count | C4: Avg Pop | D4: $/capita | E4: Spend ($)
A5: Municipalities
A6: <1K | B6: 299 | C6: 450 | D6: 2000 | E6: 269100000
A7: 1K-5K | B7: 327 | C7: 2700 | D7: 2500 | E7: 2207250000
A8: 5K-10K | B8: 168 | C8: 7100 | D8: 3000 | E8: 3578400000
A9: 10K-20K | B9: 171 | C9: 14000 | D9: 3500 | E9: 8379000000
A10: 20K-50K | B10: 180 | C10: 31000 | D10: 4200 | E10: 23436000000
A11: 50K-100K | B11: 84 | C11: 70000 | D11: 4800 | E11: 28224000000
A12: 100K+ | B12: 69 | C12: 220000 | D12: 7000 | E12: 106260000000
A13: Municipalities subtotal | B13: 1298 | E13: 172353750000
A15: Counties / Parishes
A16: <1K | B16: 0 | C16: 450 | D16: 3500 | E16: 0
A17: 1K-5K | B17: 4 | C17: 2700 | D17: 3300 | E17: 35640000
A18: 5K-10K | B18: 7 | C18: 7100 | D18: 2900 | E18: 144130000
A19: 10K-20K | B19: 13 | C19: 14000 | D19: 2700 | E19: 491400000
A20: 20K-50K | B20: 26 | C20: 31000 | D20: 2900 | E20: 2337400000
A21: 50K-100K | B21: 21 | C21: 70000 | D21: 3200 | E21: 4704000000
A22: GRAND TOTAL | B22: =B13+B23+B33+B37 | C22: 220000 | D22: 3500 | E22: =E13+E23+E33+E37
A23: Counties / Parishes subtotal | B23: =SUM(B16:B22) | E23: =SUM(E16:E22)
A25: Townships
A26: <1K | B26: 565 | C26: 450 | D26: 600 | E26: 152550000
A27: 1K-5K | B27: 460 | C27: 2700 | D27: 800 | E27: 993600000
A28: 5K-10K | B28: 167 | C28: 7100 | D28: 1100 | E28: 1304270000
A29: 10K-20K | B29: 113 | C29: 14000 | D29: 1400 | E29: 2214800000
A30: 20K-50K | B30: 89 | C30: 31000 | D30: 1600 | E30: 4414400000
A31: 50K-100K | B31: 37 | C31: 70000 | D31: 1700 | E31: 4403000000
A32: 100K+ | B32: 0 | C32: 220000 | D32: 1800 | E32: 0
A33: Townships subtotal | B33: 1431 | E33: 13482620000
A35: Special Districts
A36: (all sizes) | B36: 3050 | D36: 7600000 | E36: 23180000000
A37: Special Districts subtotal | B37: 3050 | E37: 23180000000

Sheet IN
A1: IN — Indiana
A2: Counts and estimated annual operating spend by entity type and bucket.
A4: Entity / Bucket | B4: Count | C4: Avg Pop | D4: $/capita | E4: Spend ($)
A5: Municipalities
A6: <1K | B6: 199 | C6: 450 | D6: 2000 | E6: 179100000
A7: 1K-5K | B7: 170 | C7: 2700 | D7: 2500 | E7: 1147500000
A8: 5K-10K | B8: 68 | C8: 7100 | D8: 3000 | E8: 1448400000
A9: 10K-20K | B9: 57 | C9: 14000 | D9: 3500 | E9: 2793000000
A10: 20K-50K | B10: 46 | C10: 31000 | D10: 4200 | E10: 5989200000
A11: 50K-100K | B11: 17 | C11: 70000 | D11: 4800 | E11: 5712000000
A12: 100K+ | B12: 11 | C12: 220000 | D12: 7000 | E12: 16940000000
A13: Municipalities subtotal | B13: 568 | E13: 34209200000
A15: Counties / Parishes
A16: <1K | B16: 1 | C16: 450 | D16: 3500 | E16: 1575000
A17: 1K-5K | B17: 7 | C17: 2700 | D17: 3300 | E17: 62370000
A18: 5K-10K | B18: 10 | C18: 7100 | D18: 2900 | E18: 205900000
A19: 10K-20K | B19: 15 | C19: 14000 | D19: 2700 | E19: 567000000
A20: 20K-50K | B20: 24 | C20: 31000 | D20: 2900 | E20: 2157600000
A21: 50K-100K | B21: 16 | C21: 70000 | D21: 3200 | E21: 3584000000
A22: GRAND TOTAL | B22: =B13+B23+B33+B37 | C22: 220000 | D22: 3500 | E22: =E13+E23+E33+E37
A23: Counties / Parishes subtotal | B23: =SUM(B16:B22) | E23: =SUM(E16:E22)
A25: Townships
A26: <1K | B26: 503 | C26: 450 | D26: 600 | E26: 135810000
A27: 1K-5K | B27: 322 | C27: 2700 | D27: 800 | E27: 695520000
A28: 5K-10K | B28: 91 | C28: 7100 | D28: 1100 | E28: 710710000
A29: 10K-20K | B29: 50 | C29: 14000 | D29: 1400 | E29: 980000000
A30: 20K-50K | B30: 30 | C30: 31000 | D30: 1600 | E30: 1488000000
A31: 50K-100K | B31: 10 | C31: 70000 | D31: 1700 | E31: 1190000000
A32: 100K+ | B32: 0 | C32: 220000 | D32: 1800 | E32: 0
A33: Townships subtotal | B33: 1006 | E33: 5200040000
A35: Special Districts
A36: (all sizes) | B36: 1262 | D36: 7600000 | E36: 9591200000
A37: Special Districts subtotal | B37: 1262 | E37: 9591200000

Sheet IA
A1: IA — Iowa
A2: Counts and estimated annual operating spend by entity type and bucket.
A4: Entity / Bucket | B4: Count | C4: Avg Pop | D4: $/capita | E4: Spend ($)
A5: Municipalities
A6: <1K | B6: 420 | C6: 450 | D6: 2000 | E6: 378000000
A7: 1K-5K | B7: 302 | C7: 2700 | D7: 2500 | E7: 2038500000
A8: 5K-10K | B8: 98 | C8: 7100 | D8: 3000 | E8: 2087400000
A9: 10K-20K | B9: 66 | C9: 14000 | D9: 3500 | E9: 3234000000
A10: 20K-50K | B10: 40 | C10: 31000 | D10: 4200 | E10: 5208000000
A11: 50K-100K | B11: 10 | C11: 70000 | D11: 4800 | E11: 3360000000
A12: 100K+ | B12: 5 | C12: 220000 | D12: 7000 | E12: 7700000000
A13: Municipalities subtotal | B13: 941 | E13: 24005900000
A15: Counties / Parishes
A16: <1K | B16: 2 | C16: 450 | D16: 3500 | E16: 3150000
A17: 1K-5K | B17: 15 | C17: 2700 | D17: 3300 | E17: 133650000
A18: 5K-10K | B18: 17 | C18: 7100 | D18: 2900 | E18: 350030000
A19: 10K-20K | B19: 21 | C19: 14000 | D19: 2700 | E19: 793800000
A20: 20K-50K | B20: 24 | C20: 31000 | D20: 2900 | E20: 2157600000
A21: 50K-100K | B21: 11 | C21: 70000 | D21: 3200 | E21: 2464000000
A22: GRAND TOTAL | B22: =B13+B23+B27 | C22: 220000 | D22: 3500 | E22: =E13+E23+E27
A23: Counties / Parishes subtotal | B23: =SUM(B16:B22) | E23: =SUM(E16:E22)
A25: Special Districts
A26: (all sizes) | B26: 562 | D26: 7600000 | E26: 4271200000
A27: Special Districts subtotal | B27: 562 | E27: 4271200000

Sheet KS
A1: KS — Kansas
A2: Counts and estimated annual operating spend by entity type and bucket.
A4: Entity / Bucket | B4: Count | C4: Avg Pop | D4: $/capita | E4: Spend ($)
A5: Municipalities
A6: <1K | B6: 278 | C6: 450 | D6: 2000 | E6: 250200000
A7: 1K-5K | B7: 200 | C7: 2700 | D7: 2500 | E7: 1350000000
A8: 5K-10K | B8: 65 | C8: 7100 | D8: 3000 | E8: 1384500000
A9: 10K-20K | B9: 44 | C9: 14000 | D9: 3500 | E9: 2156000000
A10: 20K-50K | B10: 27 | C10: 31000 | D10: 4200 | E10: 3515400000
A11: 50K-100K | B11: 7 | C11: 70000 | D11: 4800 | E11: 2352000000
A12: 100K+ | B12: 3 | C12: 220000 | D12: 7000 | E12: 4620000000
A13: Municipalities subtotal | B13: 624 | E13: 15628100000
A15: Counties / Parishes
A16: <1K | B16: 2 | C16: 450 | D16: 3500 | E16: 3150000
A17: 1K-5K | B17: 16 | C17: 2700 | D17: 3300 | E17: 142560000
A18: 5K-10K | B18: 17 | C18: 7100 | D18: 2900 | E18: 350030000
A19: 10K-20K | B19: 22 | C19: 14000 | D19: 2700 | E19: 831600000
A20: 20K-50K | B20: 25 | C20: 31000 | D20: 2900 | E20: 2247500000
A21: 50K-100K | B21: 12 | C21: 70000 | D21: 3200 | E21: 2688000000
A22: GRAND TOTAL | B22: =B13+B23+B33+B37 | C22: 220000 | D22: 3500 | E22: =E13+E23+E33+E37
A23: Counties / Parishes subtotal | B23: =SUM(B16:B22) | E23: =SUM(E16:E22)
A25: Townships
A26: <1K | B26: 727 | C26: 450 | D26: 600 | E26: 196290000
A27: 1K-5K | B27: 390 | C27: 2700 | D27: 800 | E27: 842400000
A28: 5K-10K | B28: 89 | C28: 7100 | D28: 1100 | E28: 695090000
A29: 10K-20K | B29: 40 | C29: 14000 | D29: 1400 | E29: 784000000
A30: 20K-50K | B30: 18 | C30: 31000 | D30: 1600 | E30: 892800000
A31: 50K-100K | B31: 4 | C31: 70000 | D31: 1700 | E31: 476000000
A32: 100K+ | B32: 0 | C32: 220000 | D32: 1800 | E32: 0
A33: Townships subtotal | B33: 1268 | E33: 3886580000
A35: Special Districts
A36: (all sizes) | B36: 1535 | D36: 7600000 | E36: 11666000000
A37: Special Districts subtotal | B37: 1535 | E37: 11666000000

Sheet KY
A1: KY — Kentucky
A2: Counts and estimated annual operating spend by entity type and bucket.
A4: Entity / Bucket | B4: Count | C4: Avg Pop | D4: $/capita | E4: Spend ($)
A5: Municipalities
A6: <1K | B6: 161 | C6: 450 | D6: 2000 | E6: 144900000
A7: 1K-5K | B7: 133 | C7: 2700 | D7: 2500 | E7: 897750000
A8: 5K-10K | B8: 48 | C8: 7100 | D8: 3000 | E8: 1022400000
A9: 10K-20K | B9: 36 | C9: 14000 | D9: 3500 | E9: 1764000000
A10: 20K-50K | B10: 26 | C10: 31000 | D10: 4200 | E10: 3385200000
A11: 50K-100K | B11: 9 | C11: 70000 | D11: 4800 | E11: 3024000000
A12: 100K+ | B12: 5 | C12: 220000 | D12: 7000 | E12: 7700000000
A13: Municipalities subtotal | B13: 418 | E13: 17938250000
A15: Counties / Parishes
A16: <1K | B16: 1 | C16: 450 | D16: 3500 | E16: 1575000
A17: 1K-5K | B17: 13 | C17: 2700 | D17: 3300 | E17: 115830000
A18: 5K-10K | B18: 16 | C18: 7100 | D18: 2900 | E18: 329440000
A19: 10K-20K | B19: 22 | C19: 14000 | D19: 2700 | E19: 831600000
A20: 20K-50K | B20: 31 | C20: 31000 | D20: 2900 | E20: 2786900000
A21: 50K-100K | B21: 18 | C21: 70000 | D21: 3200 | E21: 4032000000
A22: GRAND TOTAL | B22: =B13+B23+B27 | C22: 220000 | D22: 3500 | E22: =E13+E23+E27
A23: Counties / Parishes subtotal | B23: =SUM(B16:B22) | E23: =SUM(E16:E22)
A25: Special Districts
A26: (all sizes) | B26: 720 | D26: 7600000 | E26: 5472000000
A27: Special Districts subtotal | B27: 720 | E27: 5472000000

Sheet LA
A1: LA — Louisiana
A2: Counts and estimated annual operating spend by entity type and bucket.
A4: Entity / Bucket | B4: Count | C4: Avg Pop | D4: $/capita | E4: Spend ($)
A5: Municipalities
A6: <1K | B6: 117 | C6: 450 | D6: 2000 | E6: 105300000
A7: 1K-5K | B7: 97 | C7: 2700 | D7: 2500 | E7: 654750000
A8: 5K-10K | B8: 35 | C8: 7100 | D8: 3000 | E8: 745500000
A9: 10K-20K | B9: 27 | C9: 14000 | D9: 3500 | E9: 1323000000
A10: 20K-50K | B10: 19 | C10: 31000 | D10: 4200 | E10: 2473800000
A11: 50K-100K | B11: 6 | C11: 70000 | D11: 4800 | E11: 2016000000
A12: 100K+ | B12: 3 | C12: 220000 | D12: 7000 | E12: 4620000000
A13: Municipalities subtotal | B13: 304 | E13: 11938350000
A15: Counties / Parishes
A16: <1K | B16: 1 | C16: 450 | D16: 3500 | E16: 1575000
A17: 1K-5K | B17: 7 | C17: 2700 | D17: 3300 | E17: 62370000
A18: 5K-10K | B18: 8 | C18: 7100 | D18: 2900 | E18: 164720000
A19: 10K-20K | B19: 11 | C19: 14000 | D19: 2700 | E19: 415800000
A20: 20K-50K | B20: 16 | C20: 31000 | D20: 2900 | E20: 1438400000
A21: 50K-100K | B21: 9 | C21: 70000 | D21: 3200 | E21: 2016000000
A22: GRAND TOTAL | B22: =B13+B23+B27 | C22: 220000 | D22: 3500 | E22: =E13+E23+E27
A23: Counties / Parishes subtotal | B23: =SUM(B16:B22) | E23: =SUM(E16:E22)
A25: Special Districts
A26: (all sizes) | B26: 95 | D26: 7600000 | E26: 722000000
A27: Special Districts subtotal | B27: 95 | E27: 722000000

Sheet ME
A1: ME — Maine
A2: Counts and estimated annual operating spend by entity type and bucket.
A4: Entity / Bucket | B4: Count | C4: Avg Pop | D4: $/capita | E4: Spend ($)
A5: Municipalities
A6: <1K | B6: 10 | C6: 450 | D6: 2000 | E6: 9000000
A7: 1K-5K | B7: 7 | C7: 2700 | D7: 2500 | E7: 47250000
A8: 5K-10K | B8: 2 | C8: 7100 | D8: 3000 | E8: 42600000
A9: 10K-20K | B9: 2 | C9: 14000 | D9: 3500 | E9: 98000000
A10: 20K-50K | B10: 1 | C10: 31000 | D10: 4200 | E10: 130200000
A11: 50K-100K | B11: 0 | C11: 70000 | D11: 4800 | E11: 0
A12: 100K+ | B12: 0 | C12: 220000 | D12: 7000 | E12: 0
A13: Municipalities subtotal | B13: 22 | E13: 327050000
A15: Counties / Parishes
A16: <1K | B16: 0 | C16: 450 | D16: 3500 | E16: 0
A17: 1K-5K | B17: 3 | C17: 2700 | D17: 3300 | E17: 26730000
A18: 5K-10K | B18: 3 | C18: 7100 | D18: 2900 | E18: 61770000
A19: 10K-20K | B19: 3 | C19: 14000 | D19: 2700 | E19: 113400000
A20: 20K-50K | B20: 4 | C20: 31000 | D20: 2900 | E20: 359600000
A21: 50K-100K | B21: 2 | C21: 70000 | D21: 3200 | E21: 448000000
A22: GRAND TOTAL | B22: =B13+B23+B33+B37 | C22: 220000 | D22: 3500 | E22: =E13+E23+E33+E37
A23: Counties / Parishes subtotal | B23: =SUM(B16:B22) | E23: =SUM(E16:E22)
A25: Townships
A26: <1K | B26: 268 | C26: 450 | D26: 600 | E26: 72360000
A27: 1K-5K | B27: 144 | C27: 2700 | D27: 800 | E27: 311040000
A28: 5K-10K | B28: 32 | C28: 7100 | D28: 1100 | E28: 249920000
A29: 10K-20K | B29: 15 | C29: 14000 | D29: 1400 | E29: 294000000
A30: 20K-50K | B30: 7 | C30: 31000 | D30: 1600 | E30: 347200000
A31: 50K-100K | B31: 1 | C31: 70000 | D31: 1700 | E31: 119000000
A32: 100K+ | B32: 0 | C32: 220000 | D32: 1800 | E32: 0
A33: Townships subtotal | B33: 467 | E33: 1393520000
A35: Special Districts
A36: (all sizes) | B36: 226 | D36: 7600000 | E36: 1717600000
A37: Special Districts subtotal | B37: 226 | E37: 1717600000

Sheet MD
A1: MD — Maryland
A2: Counts and estimated annual operating spend by entity type and bucket.
A4: Entity / Bucket | B4: Count | C4: Avg Pop | D4: $/capita | E4: Spend ($)
A5: Municipalities
A6: <1K | B6: 47 | C6: 450 | D6: 2000 | E6: 42300000
A7: 1K-5K | B7: 45 | C7: 2700 | D7: 2500 | E7: 303750000
A8: 5K-10K | B8: 20 | C8: 7100 | D8: 3000 | E8: 426000000
A9: 10K-20K | B9: 18 | C9: 14000 | D9: 3500 | E9: 882000000
A10: 20K-50K | B10: 16 | C10: 31000 | D10: 4200 | E10: 2083200000
A11: 50K-100K | B11: 6 | C11: 70000 | D11: 4800 | E11: 2016000000
A12: 100K+ | B12: 5 | C12: 220000 | D12: 7000 | E12: 7700000000
A13: Municipalities subtotal | B13: 157 | E13: 13453250000
A15: Counties / Parishes
A16: <1K | B16: 0 | C16: 450 | D16: 3500 | E16: 0
A17: 1K-5K | B17: 1 | C17: 2700 | D17: 3300 | E17: 8910000
A18: 5K-10K | B18: 2 | C18: 7100 | D18: 2900 | E18: 41180000
A19: 10K-20K | B19: 4 | C19: 14000 | D19: 2700 | E19: 151200000
A20: 20K-50K | B20: 6 | C20: 31000 | D20: 2900 | E20: 539400000
A21: 50K-100K | B21: 4 | C21: 70000 | D21: 3200 | E21: 896000000
A22: GRAND TOTAL | B22: =B13+B23+B27 | C22: 220000 | D22: 3500 | E22: =E13+E23+E27
A23: Counties / Parishes subtotal | B23: =SUM(B16:B22) | E23: =SUM(E16:E22)
A25: Special Districts
A26: (all sizes) | B26: 90 | D26: 7600000 | E26: 684000000
A27: Special Districts subtotal | B27: 90 | E27: 684000000

Sheet MA
A1: MA — Massachusetts
A2: Counts and estimated annual operating spend by entity type and bucket.
A4: Entity / Bucket | B4: Count | C4: Avg Pop | D4: $/capita | E4: Spend ($)
A5: Municipalities
A6: <1K | B6: 12 | C6: 450 | D6: 2000 | E6: 10800000
A7: 1K-5K | B7: 13 | C7: 2700 | D7: 2500 | E7: 87750000
A8: 5K-10K | B8: 7 | C8: 7100 | D8: 3000 | E8: 149100000
A9: 10K-20K | B9: 7 | C9: 14000 | D9: 3500 | E9: 343000000
A10: 20K-50K | B10: 7 | C10: 31000 | D10: 4200 | E10: 911400000
A11: 50K-100K | B11: 4 | C11: 70000 | D11: 4800 | E11: 1344000000
A12: 100K+ | B12: 3 | C12: 220000 | D12: 7000 | E12: 4620000000
A13: Municipalities subtotal | B13: 53 | E13: 7466050000
A15: Counties / Parishes
A16: <1K | B16: 0 | C16: 450 | D16: 3500 | E16: 0
A17: 1K-5K | B17: 0 | C17: 2700 | D17: 3300 | E17: 0
A18: 5K-10K | B18: 0 | C18: 7100 | D18: 2900 | E18: 0
A19: 10K-20K | B19: 1 | C19: 14000 | D19: 2700 | E19: 37800000
A20: 20K-50K | B20: 1 | C20: 31000 | D20: 2900 | E20: 89900000
A21: 50K-100K | B21: 1 | C21: 70000 | D21: 3200 | E21: 224000000
A22: GRAND TOTAL | B22: =B13+B23+B33+B37 | C22: 220000 | D22: 3500 | E22: =E13+E23+E33+E37
A23: Counties / Parishes subtotal | B23: =SUM(B16:B22) | E23: =SUM(E16:E22)
A25: Townships
A26: <1K | B26: 118 | C26: 450 | D26: 600 | E26: 31860000
A27: 1K-5K | B27: 96 | C27: 2700 | D27: 800 | E27: 207360000
A28: 5K-10K | B28: 35 | C28: 7100 | D28: 1100 | E28: 273350000
A29: 10K-20K | B29: 23 | C29: 14000 | D29: 1400 | E29: 450800000
A30: 20K-50K | B30: 18 | C30: 31000 | D30: 1600 | E30: 892800000
A31: 50K-100K | B31: 8 | C31: 70000 | D31: 1700 | E31: 952000000
A32: 100K+ | B32: 0 | C32: 220000 | D32: 1800 | E32: 0
A33: Townships subtotal | B33: 298 | E33: 2808170000
A35: Special Districts
A36: (all sizes) | B36: 480 | D36: 7600000 | E36: 3648000000
A37: Special Districts subtotal | B37: 480 | E37: 3648000000

Sheet MI
A1: MI — Michigan
A2: Counts and estimated annual operating spend by entity type and bucket.
A4: Entity / Bucket | B4: Count | C4: Avg Pop | D4: $/capita | E4: Spend ($)
A5: Municipalities
A6: <1K | B6: 186 | C6: 450 | D6: 2000 | E6: 167400000
A7: 1K-5K | B7: 160 | C7: 2700 | D7: 2500 | E7: 1080000000
A8: 5K-10K | B8: 64 | C8: 7100 | D8: 3000 | E8: 1363200000
A9: 10K-20K | B9: 53 | C9: 14000 | D9: 3500 | E9: 2597000000
A10: 20K-50K | B10: 43 | C10: 31000 | D10: 4200 | E10: 5598600000
A11: 50K-100K | B11: 16 | C11: 70000 | D11: 4800 | E11: 5376000000
A12: 100K+ | B12: 11 | C12: 220000 | D12: 7000 | E12: 16940000000
A13: Municipalities subtotal | B13: 533 | E13: 33122200000
A15: Counties / Parishes
A16: <1K | B16: 1 | C16: 450 | D16: 3500 | E16: 1575000
A17: 1K-5K | B17: 7 | C17: 2700 | D17: 3300 | E17: 62370000
A18: 5K-10K | B18: 9 | C18: 7100 | D18: 2900 | E18: 185310000
A19: 10K-20K | B19: 14 | C19: 14000 | D19: 2700 | E19: 529200000
A20: 20K-50K | B20: 21 | C20: 31000 | D20: 2900 | E20: 1887900000
A21: 50K-100K | B21: 14 | C21: 70000 | D21: 3200 | E21: 3136000000
A22: GRAND TOTAL | B22: =B13+B23+B33+B37 | C22: 220000 | D22: 3500 | E22: =E13+E23+E33+E37
A23: Counties / Parishes subtotal | B23: =SUM(B16:B22) | E23: =SUM(E16:E22)
A25: Townships
A26: <1K | B26: 620 | C26: 450 | D26: 600 | E26: 167400000
A27: 1K-5K | B27: 397 | C27: 2700 | D27: 800 | E27: 857520000
A28: 5K-10K | B28: 112 | C28: 7100 | D28: 1100 | E28: 874720000
A29: 10K-20K | B29: 62 | C29: 14000 | D29: 1400 | E29: 1215200000
A30: 20K-50K | B30: 37 | C30: 31000 | D30: 1600 | E30: 1835200000
A31: 50K-100K | B31: 12 | C31: 70000 | D31: 1700 | E31: 1428000000
A32: 100K+ | B32: 0 | C32: 220000 | D32: 1800 | E32: 0
A33: Townships subtotal | B33: 1240 | E33: 6378040000
A35: Special Districts
A36: (all sizes) | B36: 451 | D36: 7600000 | E36: 3427600000
A37: Special Districts subtotal | B37: 451 | E37: 3427600000

Sheet MN
A1: MN — Minnesota
A2: Counts and estimated annual operating spend by entity type and bucket.
A4: Entity / Bucket | B4: Count | C4: Avg Pop | D4: $/capita | E4: Spend ($)
A5: Municipalities
A6: <1K | B6: 299 | C6: 450 | D6: 2000 | E6: 269100000
A7: 1K-5K | B7: 256 | C7: 2700 | D7: 2500 | E7: 1728000000
A8: 5K-10K | B8: 102 | C8: 7100 | D8: 3000 | E8: 2172600000
A9: 10K-20K | B9: 85 | C9: 14000 | D9: 3500 | E9: 4165000000
A10: 20K-50K | B10: 68 | C10: 31000 | D10: 4200 | E10: 8853600000
A11: 50K-100K | B11: 26 | C11: 70000 | D11: 4800 | E11: 8736000000
A12: 100K+ | B12: 17 | C12: 220000 | D12: 7000 | E12: 26180000000
A13: Municipalities subtotal | B13: 853 | E13: 52104300000
A15: Counties / Parishes
A16: <1K | B16: 1 | C16: 450 | D16: 3500 | E16: 1575000
A17: 1K-5K | B17: 7 | C17: 2700 | D17: 3300 | E17: 62370000
A18: 5K-10K | B18: 9 | C18: 7100 | D18: 2900 | E18: 185310000
A19: 10K-20K | B19: 15 | C19: 14000 | D19: 2700 | E19: 567000000
A20: 20K-50K | B20: 23 | C20: 31000 | D20: 2900 | E20: 2067700000
A21: 50K-100K | B21: 15 | C21: 70000 | D21: 3200 | E21: 3360000000
A22: GRAND TOTAL | B22: =B13+B23+B33+B37 | C22: 220000 | D22: 3500 | E22: =E13+E23+E33+E37
A23: Counties / Parishes subtotal | B23: =SUM(B16:B22) | E23: =SUM(E16:E22)
A25: Townships
A26: <1K | B26: 891 | C26: 450 | D26: 600 | E26: 240570000
A27: 1K-5K | B27: 570 | C27: 2700 | D27: 800 | E27: 1231200000
A28: 5K-10K | B28: 160 | C28: 7100 | D28: 1100 | E28: 1249600000
A29: 10K-20K | B29: 89 | C29: 14000 | D29: 1400 | E29: 1744400000
A30: 20K-50K | B30: 53 | C30: 31000 | D30: 1600 | E30: 2628800000
A31: 50K-100K | B31: 18 | C31: 70000 | D31: 1700 | E31: 2142000000
A32: 100K+ | B32: 0 | C32: 220000 | D32: 1800 | E32: 0
A33: Townships subtotal | B33: 1781 | E33: 9236570000
A35: Special Districts
A36: (all sizes) | B36: 482 | D36: 7600000 | E36: 3663200000
A37: Special Districts subtotal | B37: 482 | E37: 3663200000

Sheet MS
A1: MS — Mississippi
A2: Counts and estimated annual operating spend by entity type and bucket.
A4: Entity / Bucket | B4: Count | C4: Avg Pop | D4: $/capita | E4: Spend ($)
A5: Municipalities
A6: <1K | B6: 115 | C6: 450 | D6: 2000 | E6: 103500000
A7: 1K-5K | B7: 94 | C7: 2700 | D7: 2500 | E7: 634500000
A8: 5K-10K | B8: 34 | C8: 7100 | D8: 3000 | E8: 724200000
A9: 10K-20K | B9: 26 | C9: 14000 | D9: 3500 | E9: 1274000000
A10: 20K-50K | B10: 19 | C10: 31000 | D10: 4200 | E10: 2473800000
A11: 50K-100K | B11: 6 | C11: 70000 | D11: 4800 | E11: 2016000000
A12: 100K+ | B12: 3 | C12: 220000 | D12: 7000 | E12: 4620000000
A13: Municipalities subtotal | B13: 297 | E13: 11846000000
A15: Counties / Parishes
A16: <1K | B16: 1 | C16: 450 | D16: 3500 | E16: 1575000
A17: 1K-5K | B17: 9 | C17: 2700 | D17: 3300 | E17: 80190000
A18: 5K-10K | B18: 11 | C18: 7100 | D18: 2900 | E18: 226490000
A19: 10K-20K | B19: 16 | C19: 14000 | D19: 2700 | E19: 604800000
A20: 20K-50K | B20: 21 | C20: 31000 | D20: 2900 | E20: 1887900000
A21: 50K-100K | B21: 12 | C21: 70000 | D21: 3200 | E21: 2688000000
A22: GRAND TOTAL | B22: =B13+B23+B27 | C22: 220000 | D22: 3500 | E22: =E13+E23+E27
A23: Counties / Parishes subtotal | B23: =SUM(B16:B22) | E23: =SUM(E16:E22)
A25: Special Districts
A26: (all sizes) | B26: 467 | D26: 7600000 | E26: 3549200000
A27: Special Districts subtotal | B27: 467 | E27: 3549200000

Sheet MO
A1: MO — Missouri
A2: Counts and estimated annual operating spend by entity type and bucket.
A4: Entity / Bucket | B4: Count | C4: Avg Pop | D4: $/capita | E4: Spend ($)
A5: Municipalities
A6: <1K | B6: 334 | C6: 450 | D6: 2000 | E6: 300600000
A7: 1K-5K | B7: 286 | C7: 2700 | D7: 2500 | E7: 1930500000
A8: 5K-10K | B8: 115 | C8: 7100 | D8: 3000 | E8: 2449500000
A9: 10K-20K | B9: 95 | C9: 14000 | D9: 3500 | E9: 4655000000
A10: 20K-50K | B10: 76 | C10: 31000 | D10: 4200 | E10: 9895200000
A11: 50K-100K | B11: 29 | C11: 70000 | D11: 4800 | E11: 9744000000
A12: 100K+ | B12: 19 | C12: 220000 | D12: 7000 | E12: 29260000000
A13: Municipalities subtotal | B13: 954 | E13: 58234800000
A15: Counties / Parishes
A16: <1K | B16: 1 | C16: 450 | D16: 3500 | E16: 1575000
A17: 1K-5K | B17: 9 | C17: 2700 | D17: 3300 | E17: 80190000
A18: 5K-10K | B18: 13 | C18: 7100 | D18: 2900 | E18: 267670000
A19: 10K-20K | B19: 19 | C19: 14000 | D19: 2700 | E19: 718200000
A20: 20K-50K | B20: 30 | C20: 31000 | D20: 2900 | E20: 2697000000
A21: 50K-100K | B21: 19 | C21: 70000 | D21: 3200 | E21: 4256000000
A22: GRAND TOTAL | B22: =B13+B23+B33+B37 | C22: 220000 | D22: 3500 | E22: =E13+E23+E33+E37
A23: Counties / Parishes subtotal | B23: =SUM(B16:B22) | E23: =SUM(E16:E22)
A25: Townships
A26: <1K | B26: 156 | C26: 450 | D26: 600 | E26: 42120000
A27: 1K-5K | B27: 100 | C27: 2700 | D27: 800 | E27: 216000000
A28: 5K-10K | B28: 28 | C28: 7100 | D28: 1100 | E28: 218680000
A29: 10K-20K | B29: 16 | C29: 14000 | D29: 1400 | E29: 313600000
A30: 20K-50K | B30: 9 | C30: 31000 | D30: 1600 | E30: 446400000
A31: 50K-100K | B31: 3 | C31: 70000 | D31: 1700 | E31: 357000000
A32: 100K+ | B32: 0 | C32: 220000 | D32: 1800 | E32: 0
A33: Townships subtotal | B33: 312 | E33: 1593800000
A35: Special Districts
A36: (all sizes) | B36: 1620 | D36: 7600000 | E36: 12312000000
A37: Special Districts subtotal | B37: 1620 | E37: 12312000000

Sheet MT
A1: MT — Montana
A2: Counts and estimated annual operating spend by entity type and bucket.
A4: Entity / Bucket | B4: Count | C4: Avg Pop | D4: $/capita | E4: Spend ($)
A5: Municipalities
A6: <1K | B6: 57 | C6: 450 | D6: 2000 | E6: 51300000
A7: 1K-5K | B7: 41 | C7: 2700 | D7: 2500 | E7: 276750000
A8: 5K-10K | B8: 13 | C8: 7100 | D8: 3000 | E8: 276900000
A9: 10K-20K | B9: 9 | C9: 14000 | D9: 3500 | E9: 441000000
A10: 20K-50K | B10: 5 | C10: 31000 | D10: 4200 | E10: 651000000
A11: 50K-100K | B11: 1 | C11: 70000 | D11: 4800 | E11: 336000000
A12: 100K+ | B12: 1 | C12: 220000 | D12: 7000 | E12: 1540000000
A13: Municipalities subtotal | B13: 127 | E13: 3572950000
A15: Counties / Parishes
A16: <1K | B16: 1 | C16: 450 | D16: 3500 | E16: 1575000
A17: 1K-5K | B17: 8 | C17: 2700 | D17: 3300 | E17: 71280000
A18: 5K-10K | B18: 9 | C18: 7100 | D18: 2900 | E18: 185310000
A19: 10K-20K | B19: 12 | C19: 14000 | D19: 2700 | E19: 453600000
A20: 20K-50K | B20: 13 | C20: 31000 | D20: 2900 | E20: 1168700000
A21: 50K-100K | B21: 6 | C21: 70000 | D21: 3200 | E21: 1344000000
A22: GRAND TOTAL | B22: =B13+B23+B27 | C22: 220000 | D22: 3500 | E22: =E13+E23+E27
A23: Counties / Parishes subtotal | B23: =SUM(B16:B22) | E23: =SUM(E16:E22)
A25: Special Districts
A26: (all sizes) | B26: 813 | D26: 7600000 | E26: 6178800000
A27: Special Districts subtotal | B27: 813 | E27: 6178800000

Sheet NE
A1: NE — Nebraska
A2: Counts and estimated annual operating spend by entity type and bucket.
A4: Entity / Bucket | B4: Count | C4: Avg Pop | D4: $/capita | E4: Spend ($)
A5: Municipalities
A6: <1K | B6: 237 | C6: 450 | D6: 2000 | E6: 213300000
A7: 1K-5K | B7: 170 | C7: 2700 | D7: 2500 | E7: 1147500000
A8: 5K-10K | B8: 55 | C8: 7100 | D8: 3000 | E8: 1171500000
A9: 10K-20K | B9: 37 | C9: 14000 | D9: 3500 | E9: 1813000000
A10: 20K-50K | B10: 23 | C10: 31000 | D10: 4200 | E10: 2994600000
A11: 50K-100K | B11: 6 | C11: 70000 | D11: 4800 | E11: 2016000000
A12: 100K+ | B12: 2 | C12: 220000 | D12: 7000 | E12: 3080000000
A13: Municipalities subtotal | B13: 530 | E13: 12435900000
A15: Counties / Parishes
A16: <1K | B16: 2 | C16: 450 | D16: 3500 | E16: 3150000
A17: 1K-5K | B17: 14 | C17: 2700 | D17: 3300 | E17: 124740000
A18: 5K-10K | B18: 16 | C18: 7100 | D18: 2900 | E18: 329440000
A19: 10K-20K | B19: 20 | C19: 14000 | D19: 2700 | E19: 756000000
A20: 20K-50K | B20: 23 | C20: 31000 | D20: 2900 | E20: 2067700000
A21: 50K-100K | B21: 10 | C21: 70000 | D21: 3200 | E21: 2240000000
A22: GRAND TOTAL | B22: =B13+B23+B33+B37 | C22: 220000 | D22: 3500 | E22: =E13+E23+E33+E37
A23: Counties / Parishes subtotal | B23: =SUM(B16:B22) | E23: =SUM(E16:E22)
A25: Townships
A26: <1K | B26: 238 | C26: 450 | D26: 600 | E26: 64260000
A27: 1K-5K | B27: 128 | C27: 2700 | D27: 800 | E27: 276480000
A28: 5K-10K | B28: 29 | C28: 7100 | D28: 1100 | E28: 226490000
A29: 10K-20K | B29: 13 | C29: 14000 | D29: 1400 | E29: 254800000
A30: 20K-50K | B30: 6 | C30: 31000 | D30: 1600 | E30: 297600000
A31: 50K-100K | B31: 1 | C31: 70000 | D31: 1700 | E31: 119000000
A32: 100K+ | B32: 0 | C32: 220000 | D32: 1800 | E32: 0
A33: Townships subtotal | B33: 415 | E33: 1238630000
A35: Special Districts
A36: (all sizes) | B36: 1300 | D36: 7600000 | E36: 9880000000
A37: Special Districts subtotal | B37: 1300 | E37: 9880000000

Sheet NV
A1: NV — Nevada
A2: Counts and estimated annual operating spend by entity type and bucket.
A4: Entity / Bucket | B4: Count | C4: Avg Pop | D4: $/capita | E4: Spend ($)
A5: Municipalities
A6: <1K | B6: 6 | C6: 450 | D6: 2000 | E6: 5400000
A7: 1K-5K | B7: 5 | C7: 2700 | D7: 2500 | E7: 33750000
A8: 5K-10K | B8: 2 | C8: 7100 | D8: 3000 | E8: 42600000
A9: 10K-20K | B9: 2 | C9: 14000 | D9: 3500 | E9: 98000000
A10: 20K-50K | B10: 2 | C10: 31000 | D10: 4200 | E10: 260400000
A11: 50K-100K | B11: 1 | C11: 70000 | D11: 4800 | E11: 336000000
A12: 100K+ | B12: 1 | C12: 220000 | D12: 7000 | E12: 1540000000
A13: Municipalities subtotal | B13: 19 | E13: 2316150000
A15: Counties / Parishes
A16: <1K | B16: 0 | C16: 450 | D16: 3500 | E16: 0
A17: 1K-5K | B17: 1 | C17: 2700 | D17: 3300 | E17: 8910000
A18: 5K-10K | B18: 2 | C18: 7100 | D18: 2900 | E18: 41180000
A19: 10K-20K | B19: 2 | C19: 14000 | D19: 2700 | E19: 75600000
A20: 20K-50K | B20: 4 | C20: 31000 | D20: 2900 | E20: 359600000
A21: 50K-100K | B21: 3 | C21: 70000 | D21: 3200 | E21: 672000000
A22: GRAND TOTAL | B22: =B13+B23+B27 | C22: 220000 | D22: 3500 | E22: =E13+E23+E27
A23: Counties / Parishes subtotal | B23: =SUM(B16:B22) | E23: =SUM(E16:E22)
A25: Special Districts
A26: (all sizes) | B26: 175 | D26: 7600000 | E26: 1330000000
A27: Special Districts subtotal | B27: 175 | E27: 1330000000

Sheet NH
A1: NH — New Hampshire
A2: Counts and estimated annual operating spend by entity type and bucket.
A4: Entity / Bucket | B4: Count | C4: Avg Pop | D4: $/capita | E4: Spend ($)
A5: Municipalities
A6: <1K | B6: 5 | C6: 450 | D6: 2000 | E6: 4500000
A7: 1K-5K | B7: 4 | C7: 2700 | D7: 2500 | E7: 27000000
A8: 5K-10K | B8: 2 | C8: 7100 | D8: 3000 | E8: 42600000
A9: 10K-20K | B9: 1 | C9: 14000 | D9: 3500 | E9: 49000000
A10: 20K-50K | B10: 1 | C10: 31000 | D10: 4200 | E10: 130200000
A11: 50K-100K | B11: 0 | C11: 70000 | D11: 4800 | E11: 0
A12: 100K+ | B12: 0 | C12: 220000 | D12: 7000 | E12: 0
A13: Municipalities subtotal | B13: 13 | E13: 253300000
A15: Counties / Parishes
A16: <1K | B16: 0 | C16: 450 | D16: 3500 | E16: 0
A17: 1K-5K | B17: 1 | C17: 2700 | D17: 3300 | E17: 8910000
A18: 5K-10K | B18: 1 | C18: 7100 | D18: 2900 | E18: 20590000
A19: 10K-20K | B19: 2 | C19: 14000 | D19: 2700 | E19: 75600000
A20: 20K-50K | B20: 3 | C20: 31000 | D20: 2900 | E20: 269700000
A21: 50K-100K | B21: 2 | C21: 70000 | D21: 3200 | E21: 448000000
A22: GRAND TOTAL | B22: =B13+B23+B33+B37 | C22: 220000 | D22: 3500 | E22: =E13+E23+E33+E37
A23: Counties / Parishes subtotal | B23: =SUM(B16:B22) | E23: =SUM(E16:E22)
A25: Townships
A26: <1K | B26: 116 | C26: 450 | D26: 600 | E26: 31320000
A27: 1K-5K | B27: 71 | C27: 2700 | D27: 800 | E27: 153360000
A28: 5K-10K | B28: 18 | C28: 7100 | D28: 1100 | E28: 140580000
A29: 10K-20K | B29: 9 | C29: 14000 | D29: 1400 | E29: 176400000
A30: 20K-50K | B30: 5 | C30: 31000 | D30: 1600 | E30: 248000000
A31: 50K-100K | B31: 2 | C31: 70000 | D31: 1700 | E31: 238000000
A32: 100K+ | B32: 0 | C32: 220000 | D32: 1800 | E32: 0
A33: Townships subtotal | B33: 221 | E33: 987660000
A35: Special Districts
A36: (all sizes) | B36: 142 | D36: 7600000 | E36: 1079200000
A37: Special Districts subtotal | B37: 142 | E37: 1079200000

Sheet NJ
A1: NJ — New Jersey
A2: Counts and estimated annual operating spend by entity type and bucket.
A4: Entity / Bucket | B4: Count | C4: Avg Pop | D4: $/capita | E4: Spend ($)
A5: Municipalities
A6: <1K | B6: 130 | C6: 450 | D6: 2000 | E6: 117000000
A7: 1K-5K | B7: 142 | C7: 2700 | D7: 2500 | E7: 958500000
A8: 5K-10K | B8: 73 | C8: 7100 | D8: 3000 | E8: 1554900000
A9: 10K-20K | B9: 74 | C9: 14000 | D9: 3500 | E9: 3626000000
A10: 20K-50K | B10: 79 | C10: 31000 | D10: 4200 | E10: 10285800000
A11: 50K-100K | B11: 37 | C11: 70000 | D11: 4800 | E11: 12432000000
A12: 100K+ | B12: 30 | C12: 220000 | D12: 7000 | E12: 46200000000
A13: Municipalities subtotal | B13: 565 | E13: 75174200000
A15: Counties / Parishes
A16: <1K | B16: 0 | C16: 450 | D16: 3500 | E16: 0
A17: 1K-5K | B17: 1 | C17: 2700 | D17: 3300 | E17: 8910000
A18: 5K-10K | B18: 2 | C18: 7100 | D18: 2900 | E18: 41180000
A19: 10K-20K | B19: 3 | C19: 14000 | D19: 2700 | E19: 113400000
A20: 20K-50K | B20: 5 | C20: 31000 | D20: 2900 | E20: 449500000
A21: 50K-100K | B21: 4 | C21: 70000 | D21: 3200 | E21: 896000000
A22: GRAND TOTAL | B22: =B13+B23+B27 | C22: 220000 | D22: 3500 | E22: =E13+E23+E27
A23: Counties / Parishes subtotal | B23: =SUM(B16:B22) | E23: =SUM(E16:E22)
A25: Special Districts
A26: (all sizes) | B26: 281 | D26: 7600000 | E26: 2135600000
A27: Special Districts subtotal | B27: 281 | E27: 2135600000

Sheet NM
A1: NM — New Mexico
A2: Counts and estimated annual operating spend by entity type and bucket.
A4: Entity / Bucket | B4: Count | C4: Avg Pop | D4: $/capita | E4: Spend ($)
A5: Municipalities
A6: <1K | B6: 41 | C6: 450 | D6: 2000 | E6: 36900000
A7: 1K-5K | B7: 33 | C7: 2700 | D7: 2500 | E7: 222750000
A8: 5K-10K | B8: 12 | C8: 7100 | D8: 3000 | E8: 255600000
A9: 10K-20K | B9: 9 | C9: 14000 | D9: 3500 | E9: 441000000
A10: 20K-50K | B10: 7 | C10: 31000 | D10: 4200 | E10: 911400000
A11: 50K-100K | B11: 2 | C11: 70000 | D11: 4800 | E11: 672000000
A12: 100K+ | B12: 1 | C12: 220000 | D12: 7000 | E12: 1540000000
A13: Municipalities subtotal | B13: 105 | E13: 4079650000
A15: Counties / Parishes
A16: <1K | B16: 0 | C16: 450 | D16: 3500 | E16: 0
A17: 1K-5K | B17: 4 | C17: 2700 | D17: 3300 | E17: 35640000
A18: 5K-10K | B18: 4 | C18: 7100 | D18: 2900 | E18: 82360000
A19: 10K-20K | B19: 6 | C19: 14000 | D19: 2700 | E19: 226800000
A20: 20K-50K | B20: 9 | C20: 31000 | D20: 2900 | E20: 809100000
A21: 50K-100K | B21: 5 | C21: 70000 | D21: 3200 | E21: 1120000000
A22: GRAND TOTAL | B22: =B13+B23+B27 | C22: 220000 | D22: 3500 | E22: =E13+E23+E27
A23: Counties / Parishes subtotal | B23: =SUM(B16:B22) | E23: =SUM(E16:E22)
A25: Special Districts
A26: (all sizes) | B26: 685 | D26: 7600000 | E26: 5206000000
A27: Special Districts subtotal | B27: 685 | E27: 5206000000

Sheet NY
A1: NY — New York
A2: Counts and estimated annual operating spend by entity type and bucket.
A4: Entity / Bucket | B4: Count | C4: Avg Pop | D4: $/capita | E4: Spend ($)
A5: Municipalities
A6: <1K | B6: 142 | C6: 450 | D6: 2000 | E6: 127800000
A7: 1K-5K | B7: 155 | C7: 2700 | D7: 2500 | E7: 1046250000
A8: 5K-10K | B8: 79 | C8: 7100 | D8: 3000 | E8: 1682700000
A9: 10K-20K | B9: 81 | C9: 14000 | D9: 3500 | E9: 3969000000
A10: 20K-50K | B10: 85 | C10: 31000 | D10: 4200 | E10: 11067000000
A11: 50K-100K | B11: 40 | C11: 70000 | D11: 4800 | E11: 13440000000
A12: 100K+ | B12: 32 | C12: 220000 | D12: 7000 | E12: 49280000000
A13: Municipalities subtotal | B13: 614 | E13: 80612750000
A15: Counties / Parishes
A16: <1K | B16: 0 | C16: 450 | D16: 3500 | E16: 0
A17: 1K-5K | B17: 2 | C17: 2700 | D17: 3300 | E17: 17820000
A18: 5K-10K | B18: 4 | C18: 7100 | D18: 2900 | E18: 82360000
A19: 10K-20K | B19: 7 | C19: 14000 | D19: 2700 | E19: 264600000
A20: 20K-50K | B20: 15 | C20: 31000 | D20: 2900 | E20: 1348500000
A21: 50K-100K | B21: 12 | C21: 70000 | D21: 3200 | E21: 2688000000
A22: GRAND TOTAL | B22: =B13+B23+B33+B37 | C22: 220000 | D22: 3500 | E22: =E13+E23+E33+E37
A23: Counties / Parishes subtotal | B23: =SUM(B16:B22) | E23: =SUM(E16:E22)
A25: Townships
A26: <1K | B26: 368 | C26: 450 | D26: 600 | E26: 99360000
A27: 1K-5K | B27: 300 | C27: 2700 | D27: 800 | E27: 648000000
A28: 5K-10K | B28: 109 | C28: 7100 | D28: 1100 | E28: 851290000
A29: 10K-20K | B29: 74 | C29: 14000 | D29: 1400 | E29: 1450400000
A30: 20K-50K | B30: 58 | C30: 31000 | D30: 1600 | E30: 2876800000
A31: 50K-100K | B31: 24 | C31: 70000 | D31: 1700 | E31: 2856000000
A32: 100K+ | B32: 0 | C32: 220000 | D32: 1800 | E32: 0
A33: Townships subtotal | B33: 933 | E33: 8781850000
A35: Special Districts
A36: (all sizes) | B36: 1183 | D36: 7600000 | E36: 8990800000
A37: Special Districts subtotal | B37: 1183 | E37: 8990800000

Sheet NC
A1: NC — North Carolina
A2: Counts and estimated annual operating spend by entity type and bucket.
A4: Entity / Bucket | B4: Count | C4: Avg Pop | D4: $/capita | E4: Spend ($)
A5: Municipalities
A6: <1K | B6: 193 | C6: 450 | D6: 2000 | E6: 173700000
A7: 1K-5K | B7: 166 | C7: 2700 | D7: 2500 | E7: 1120500000
A8: 5K-10K | B8: 66 | C8: 7100 | D8: 3000 | E8: 1405800000
A9: 10K-20K | B9: 55 | C9: 14000 | D9: 3500 | E9: 2695000000
A10: 20K-50K | B10: 44 | C10: 31000 | D10: 4200 | E10: 5728800000
A11: 50K-100K | B11: 17 | C11: 70000 | D11: 4800 | E11: 5712000000
A12: 100K+ | B12: 11 | C12: 220000 | D12: 7000 | E12: 16940000000
A13: Municipalities subtotal | B13: 552 | E13: 33775800000
A15: Counties / Parishes
A16: <1K | B16: 1 | C16: 450 | D16: 3500 | E16: 1575000
A17: 1K-5K | B17: 8 | C17: 2700 | D17: 3300 | E17: 71280000
A18: 5K-10K | B18: 11 | C18: 7100 | D18: 2900 | E18: 226490000
A19: 10K-20K | B19: 17 | C19: 14000 | D19: 2700 | E19: 642600000
A20: 20K-50K | B20: 26 | C20: 31000 | D20: 2900 | E20: 2337400000
A21: 50K-100K | B21: 17 | C21: 70000 | D21: 3200 | E21: 3808000000
A22: GRAND TOTAL | B22: =B13+B23+B27 | C22: 220000 | D22: 3500 | E22: =E13+E23+E27
A23: Counties / Parishes subtotal | B23: =SUM(B16:B22) | E23: =SUM(E16:E22)
A25: Special Districts
A26: (all sizes) | B26: 311 | D26: 7600000 | E26: 2363600000
A27: Special Districts subtotal | B27: 311 | E27: 2363600000

Sheet ND
A1: ND — North Dakota
A2: Counts and estimated annual operating spend by entity type and bucket.
A4: Entity / Bucket | B4: Count | C4: Avg Pop | D4: $/capita | E4: Spend ($)
A5: Municipalities
A6: <1K | B6: 159 | C6: 450 | D6: 2000 | E6: 143100000
A7: 1K-5K | B7: 115 | C7: 2700 | D7: 2500 | E7: 776250000
A8: 5K-10K | B8: 37 | C8: 7100 | D8: 3000 | E8: 788100000
A9: 10K-20K | B9: 25 | C9: 14000 | D9: 3500 | E9: 1225000000
A10: 20K-50K | B10: 15 | C10: 31000 | D10: 4200 | E10: 1953000000
A11: 50K-100K | B11: 4 | C11: 70000 | D11: 4800 | E11: 1344000000
A12: 100K+ | B12: 2 | C12: 220000 | D12: 7000 | E12: 3080000000
A13: Municipalities subtotal | B13: 357 | E13: 9309450000
A15: Counties / Parishes
A16: <1K | B16: 1 | C16: 450 | D16: 3500 | E16: 1575000
A17: 1K-5K | B17: 8 | C17: 2700 | D17: 3300 | E17: 71280000
A18: 5K-10K | B18: 9 | C18: 7100 | D18: 2900 | E18: 185310000
A19: 10K-20K | B19: 11 | C19: 14000 | D19: 2700 | E19: 415800000
A20: 20K-50K | B20: 13 | C20: 31000 | D20: 2900 | E20: 1168700000
A21: 50K-100K | B21: 6 | C21: 70000 | D21: 3200 | E21: 1344000000
A22: GRAND TOTAL | B22: =B13+B23+B33+B37 | C22: 220000 | D22: 3500 | E22: =E13+E23+E33+E37
A23: Counties / Parishes subtotal | B23: =SUM(B16:B22) | E23: =SUM(E16:E22)
A25: Townships
